Workbook
Name Print_Area_MI: 'סה"כ טעינת מטענים - טבלה'!#REF!
Name Print_Area_MI: 'סה"כ מטענים - טבלה '!$B$3:$R$39
Name Print_Area_MI: 'סה"כ פריקת מטענים - טבלה '!#REF!
Name Print_Area_MI: 'סה"כ תנועת מטענים - טבלה'!#REF!

Sheet סה"כ מטענים - טבלה 
A1: Ministry Of Transport - Administration of Shipping & Ports | R1: משרד התחבורה - רשות הספנות והנמלים
A2: Economics and International Affairs Division | R2: אגף כלכלה וקשרי חוץ
A3: TABLE 1 : Total Traffic Cargo in Israeli Ports | R3: לוח 1 : תנועת סה"כ המטענים בנמלי ישראל
A4: Thousand tons | R4: אלפי טונות
A5: Loaded | E5: נטענו | F5: Unloaded | J5: נפרקו | L5: נפרקו ונטענו - סך הכל
L6: Loaded and unloaded - total
A7: מספנות | B7: אילת | C7: אשדוד | D7: חיפה | E7: כל הנמלים | F7: מספנות | G7: אילת | H7: אשדוד | I7: חיפה | J7: כל הנמלים | K7: מספנות | L7: אילת | M7: אשדוד | N7: חיפה | O7: כל הנמלים | Q7: חודשים | R7: שנה
A8: shipyards | B8: Eilat | C8: Ashdod | D8: Haifa | E8: All Ports | F8: shipyards | G8: Eilat | H8: Ashdod | I8: Haifa | J8: All Ports | K8: shipyards | L8: Eilat | M8: Ashdod | N8: Haifa | O8: All Ports | Q8: months | R8: Year
B9: 1432 | C9: 4557 | D9: 4890 | E9: 10879 | G9: 264 | H9: 11410 | I9: 8610 | J9: 20284 | L9: 1696 | M9: 15967 | N9: 13501 | O9: 31163 | R9: 1995
B10: 1138 | C10: 5036 | D10: 4507 | E10: 10680 | G10: 289 | H10: 10096 | I10: 8347 | J10: 18732 | L10: 1427 | M10: 15132 | N10: 12853 | O10: 29412 | R10: 1996
B11: 1866 | C11: 4785 | D11: 5564 | E11: 12214 | G11: 245 | H11: 10821 | I11: 9539 | J11: 20606 | L11: 2111 | M11: 15606 | N11: 15103 | O11: 32820 | R11: 1997
B12: 1459 | C12: 5436 | D12: 6593 | E12: 13489 | G12: 225 | H12: 10017 | I12: 10089 | J12: 20330 | L12: 1684 | M12: 15453 | N12: 16682 | O12: 33819 | R12: 1998
B13: 1440 | C13: 5270 | D13: 6164 | E13: 12875 | G13: 232 | H13: 10924 | I13: 11039 | J13: 22195 | L13: 1672 | M13: 16194 | N13: 17203 | O13: 35069 | R13: 1999
B14: 1545 | C14: 5259 | D14: 7062 | E14: 13866 | G14: 254 | H14: 10499 | I14: 11472 | J14: 22226 | L14: 1799 | M14: 15758 | N14: 18534 | O14: 36091 | R14: 2000
B15: 1438 | C15: 5241 | D15: 6658 | E15: 13338 | G15: 258 | H15: 8389 | I15: 10072 | J15: 18719 | L15: =G15+B15 -> 1696 | M15: 13630 | N15: 16731 | O15: 32057 | R15: 2001
B16: 1413 | C16: 5471 | D16: 6979 | E16: 13863 | G16: 200 | H16: 9250 | I16: 10094 | J16: 19545 | L16: =G16+B16 -> 1613 | M16: 14722 | N16: 17073 | O16: 33408 | R16: 2002
B17: 1760.467 | C17: 5176.897 | D17: 8029.6062 | E17: 15075.889 | G17: 234.9648 | H17: 8885.3984 | I17: 10775.365 | J17: 19895.728 | L17: =G17+B17 -> 1995.4318 | M17: 14062.295 | N17: 18804.971 | O17: 34971.617 | R17: 2003
B18: 1784.3859 | C18: 5721.8554 | D18: 8200.1941 | E18: 15706.435 | G18: 326.016 | H18: 8727.6761 | I18: 12337.941 | J18: 21391.633 | L18: =G18+B18 -> 2110.4019 | M18: 14449.531 | N18: 20538.135 | O18: 37098.068 | R18: 2004
B19: =SUM(B36:B39) -> 2202.756 | C19: =SUM(C36:C39) -> 5352.966 | D19: =SUM(D36:D39) -> 9079.456 | E19: =SUM(E36:E39) -> 16635.178 | G19: =SUM(G36:G39) -> 291.321 | H19: =SUM(H36:H39) -> 8874.972 | I19: =SUM(I36:I39) -> 11911.177 | J19: =SUM(J36:J39) -> 21077.47 | L19: =G19+B19 -> 2494.077 | M19: =SUM(M36:M39) -> 14227.938 | N19: =SUM(N36:N39) -> 20990.633 | O19: =SUM(O36:O39) -> 37712.648 | R19: 2005
B20: 1639.335 | C20: 5516 | D20: 8693 | E20: 15848.335 | G20: 269 | H20: 9626 | I20: 10508 | J20: 20404 | L20: 1908.335 | M20: 15144 | N20: 19202 | O20: 36253.335 | R20: 2006
B21: =SUM(B46:B49) -> 2309.689 | C21: =SUM(C46:C49) -> 6126.368 | D21: =SUM(D46:D49) -> 9311.392 | E21: =SUM(E46:E49) -> 17747.449 | G21: =SUM(G46:G49) -> 224.99 | H21: =SUM(H46:H49) -> 10105.497 | I21: =SUM(I46:I49) -> 12145.549 | J21: =SUM(J46:J49) -> 22476.036 | L21: =SUM(L46:L49) -> 2534.679 | M21: =SUM(M46:M49) -> 16231.865 | N21: =SUM(N46:N49) -> 21456.941 | O21: =SUM(O46:O49) -> 40223.485 | R21: 2007
A22: 0 | B22: =B54+B58+B62+B66 -> 2356.933 | C22: =C54+C58+C62+C66 -> 5804.292 | D22: =D54+D58+D62+D66 -> 9970.744 | E22: =E54+E58+E62+E66 -> 18131.969 | F22: 232.33588 | G22: =G54+G58+G62+G66 -> 220.335 | H22: =H54+H58+H62+H66 -> 10047.229 | I22: =I54+I58+I62+I66 -> 12589.633 | J22: =J54+J58+J62+J66 -> 22857.197 | K22: =F22+A22 -> 232.33588 | L22: =L54+L58+L62+L66 -> 2577.268 | M22: =M54+M58+M62+M66 -> 15851.521 | N22: =N54+N58+N62+N66 -> 22560.377 | O22: =O54+O58+O62+O66 -> 40989.166 | R22: 2008
A23: =A71+A75+A79+A83 -> 19.502 | B23: =B71+B75+B79+B83 -> 1585.651 | C23: =C71+C75+C79+C83 -> 4918.014 | D23: =D71+D75+D79+D83 -> 8875.588 | E23: =E71+E75+E79+E83 -> 15398.755 | F23: =F71+F75+F79+F83 -> 436.4007 | G23: =G71+G75+G79+G83 -> 173.582 | H23: =H71+H75+H79+H83 -> 9997.253 | ... O23: =O71+O75+O79+O83 -> 36943.195 | R23: 2009
A24: =A88+A92+A96+A100 -> 9.237 | B24: =B88+B92+B96+B100 -> 2254.737 | C24: =C88+C92+C96+C100 -> 7307.861 | D24: =D88+D92+D96+D100 -> 9697.4469 | E24: =E88+E92+E96+E100 -> 19269.282 | F24: =F88+F92+F96+F100 -> 709.82099 | G24: =G88+G92+G96+G100 -> 66.271 | H24: =H88+H92+H96+H100 -> 11227.143 | ... O24: =O88+O92+O96+O100 -> 43412.548 | R24: 2010
A25: =A105+A109+A113+A117 -> 24.571 | B25: =B105+B109+B113+B117 -> 2119.32 | C25: =C105+C109+C113+C117 -> 7224.6731 | D25: =D105+D109+D113+D117 -> 10221.252 | E25: =E105+E109+E113+E117 -> 19589.816 | F25: =F105+F109+F113+F117 -> 1000.7894 | G25: =G105+G109+G113+G117 -> 161.1249 | H25: =H105+H109+H113+H117 -> 11990.761 | ... O25: =O105+O109+O113+O117 -> 45073.48 | R25: 2011
A26: =A122+A126+A130+A134 -> 32.164 | B26: =B122+B126+B130+B134 -> 1456.209 | C26: =C122+C126+C130+C134 -> 7231.6741 | D26: =D122+D126+D130+D134 -> 10709.436 | E26: =E122+E126+E130+E134 -> 19429.483 | F26: =F122+F126+F130+F134 -> 1270.11 | G26: =G122+G126+G130+G134 -> 105.57 | H26: =H122+H126+H130+H134 -> 12382.74 | ... O26: =O122+O126+O130+O134 -> 46466.584 | R26: 2012
A27: =A139+A143+A147+A151 -> 11.793 | B27: =B139+B143+B147+B151 -> 1921.3107 | C27: =C139+C143+C147+C151 -> 6829.0077 | D27: =D139+D143+D147+D151 -> 11700.985 | E27: =E139+E143+E147+E151 -> 20463.097 | F27: =F139+F143+F147+F151 -> 1655.099 | G27: =G139+G143+G147+G151 -> 160.61696 | H27: =H139+H143+H147+H151 -> 12384.553 | ... O27: =O139+O143+O147+O151 -> 48750.218 | R27: 2013
A28: =A156+A160+A164+A168 -> 16.855 | B28: =B156+B160+B164+B168 -> 2126.0743 | C28: =C156+C160+C164+C168 -> 8264.3546 | D28: =D156+D160+D164+D168 -> 10877.018 | E28: =E156+E160+E164+E168 -> 21284.302 | F28: =F156+F160+F164+F168 -> 1913.903 | G28: =G156+G160+G164+G168 -> 184.1447 | H28: =H156+H160+H164+H168 -> 13290.384 | ... O28: =O156+O160+O164+O168 -> 53295.873 | R28: 2014
A29: =A173+A177+A181+A185 -> 5.71 | B29: =B173+B177+B181+B185 -> 1891.2727 | C29: =C173+C177+C181+C185 -> 7948.6514 | D29: =D173+D177+D181+D185 -> 10327.323 | E29: =E173+E177+E181+E185 -> 20172.957 | F29: =F173+F177+F181+F185 -> 2130.103 | G29: =G173+G177+G181+G185 -> 211.91207 | H29: =H173+H177+H181+H185 -> 14324.833 | ... O29: =O173+O177+O181+O185 -> 53771.91 | R29: 2015
A30: =A190+A194+A198+A202 -> 2.337 | B30: =B190+B194+B198+B202 -> 1891.1233 | C30: =C190+C194+C198+C202 -> 8694.1246 | D30: =D190+D194+D198+D202 -> 10149.986 | E30: =E190+E194+E198+E202 -> 20737.57 | F30: =F190+F194+F198+F202 -> 2823.185 | G30: =G190+G194+G198+G202 -> 218.293 | H30: =H190+H194+H198+H202 -> 15392.293 | ... O30: =O190+O194+O198+O202 -> 57047.926 | R30: 2016
A31: =A207+A211+A215+A219 -> 0.136 | B31: =B207+B211+B215+B219 -> 2018.11 | C31: =C207+C211+C215+C219 -> 8375.2218 | D31: =D207+D211+D215+D219 -> 10112.283 | E31: =E207+E211+E215+E219 -> 20505.75 | F31: =F207+F211+F215+F219 -> 2928.1174 | G31: =G207+G211+G215+G219 -> 153.34512 | H31: =H207+H211+H215+H219 -> 15209.327 | ... O31: =O207+O211+O215+O219 -> 57936.062 | R31: 2017
A32: =A224+A228+A232+A236 -> 2.137 | B32: =B224+B228+B232+B236 -> 2114.266 | C32: =C224+C228+C232+C236 -> 7702.5772 | D32: =D224+D228+D232+D236 -> 10414.278 | E32: =E224+E228+E232+E236 -> 20233.259 | F32: =F224+F228+F232+F236 -> 3416.685 | G32: =G224+G228+G232+G236 -> 175.799 | H32: =H224+H228+H232+H236 -> 15772.47 | ... O32: =O224+O228+O232+O236 -> 58714.966 | R32: 2018
A33: =A241+A245+A249+A253 -> 0 | B33: =B241+B245+B249+B253 -> 1750.9701 | C33: =C241+C245+C249+C253 -> 7751.2784 | D33: =D241+D245+D249+D253 -> 10107.839 | E33: =E241+E245+E249+E253 -> 19610.087 | F33: =F241+F245+F249+F253 -> 3074.337 | G33: =G241+G245+G249+G253 -> 193.747 | H33: =H241+H245+H249+H253 -> 15838.642 | ... O33: =O241+O245+O249+O253 -> 57693.241 | R33: 2019
A34: =A258+A262+A266+A270 -> 0 | B34: =B258+B262+B266+B270 -> 2075.403 | C34: =C258+C262+C266+C270 -> 7908.6101 | D34: =D258+D262+D266+D270 -> 9139.3927 | E34: =E258+E262+E266+E270 -> 19123.406 | F34: =F258+F262+F266+F270 -> 4456.5525 | G34: =G258+G262+G266+G270 -> 149.168 | H34: =H258+H262+H266+H270 -> 16065.036 | ... O34: =O258+O262+O266+O270 -> 57452.724 | R34: 2020
B36: 600.768 | C36: 1459.112 | D36: 2044.352 | E36: =SUM(B36:D36) -> 4104.232 | G36: 53.226 | H36: 2105.006 | I36: 2822.7655 | J36: =SUM(G36:I36) -> 4980.9975 | L36: =G36+B36 -> 653.994 | M36: =H36+C36 -> 3564.118 | N36: =I36+D36 -> 4867.1175 | O36: =J36+E36 -> 9085.2295 | Q36: 01-03 | R36: 2005
B37: 391.86 | C37: 1587.206 | D37: 2557.609 | E37: =SUM(B37:D37) -> 4536.675 | G37: 85.207 | H37: 2220.072 | I37: 3087.518 | J37: =SUM(G37:I37) -> 5392.797 | L37: =G37+B37 -> 477.067 | M37: =H37+C37 -> 3807.278 | N37: =I37+D37 -> 5645.127 | O37: =J37+E37 -> 9929.472 | Q37: 04-06
B38: 651.862 | C38: 1193.714 | D38: 2357.055 | E38: =SUM(B38:D38) -> 4202.631 | G38: 76.459 | H38: 2304.379 | I38: 3041.695 | J38: =SUM(G38:I38) -> 5422.533 | L38: =G38+B38 -> 728.321 | M38: =H38+C38 -> 3498.093 | N38: =I38+D38 -> 5398.75 | O38: =J38+E38 -> 9625.164 | Q38: 07-09
B39: 558.266 | C39: 1112.934 | D39: 2120.44 | E39: =SUM(B39:D39) -> 3791.64 | G39: 76.429 | H39: 2245.515 | I39: 2959.199 | J39: =SUM(G39:I39) -> 5281.143 | L39: =G39+B39 -> 634.695 | M39: =H39+C39 -> 3358.449 | N39: =I39+D39 -> 5079.639 | O39: =J39+E39 -> 9072.783 | Q39: 10-12
B41: 253.335 | C41: 1170 | D41: 2221 | E41: 3644.335 | G41: 49 | H41: 2240 | I41: 2719 | J41: 5009 | L41: 302.335 | M41: 3412 | N41: 4941 | O41: 8654.335 | Q41: 01-03 | R41: 2006
B42: 356 | C42: 1294 | D42: 2688 | E42: =SUM(B42:D42) -> 4338 | G42: 79 | H42: 2374 | I42: 2837 | J42: =SUM(G42:I42) -> 5290 | L42: =G42+B42 -> 435 | M42: =H42+C42 -> 3668 | N42: =I42+D42 -> 5525 | O42: =J42+E42 -> 9628 | P42: 3076 | Q42: 04-06
...

Sheet לא להפצה
J4: תנועת מטענים בטונות(מכולות גם ב-TEU)- חתך נמלים
C6: נמל | D6: נמל חיפה: | J6: נמל אשדוד: | P6: נמל אילת: | V6: סה"כ | Y6: נמל חיפה | Z6: נמל אשדוד | AA6: נמל אילת | AB6: סה"כ
B7: שנה | C7: רבעון | D7: סה"כ פריקה וטעינה | E7: סה"כ פריקה | F7: סה"כ טעינה | G7: מכולות טון TEU | I7: מספר נוסעים | J7: סה"כ פריקה וטעינה | K7: סה"כ פריקה | L7: סה"כ טעינה | M7: מכולות טון TEU | O7: מספר נוסעים | P7: סה"כ פריקה וטעינה | Q7: סה"כ פריקה | R7: סה"כ טעינה | S7: מכולות טון TEU | U7: מספר נוסעים | X7: שנה | Y7: סה"כ פריקה וטעינה | Z7: סה"כ פריקה וטעינה | AA7: סה"כ פריקה וטעינה
B8: 2005 | C8: רבעון 1 | D8: =Y8/1000 -> 5079.6393 | J8: =Z8/1000 -> 3358.4489 | P8: =AA8/1000 -> 634.708 | V8: =D8+J8+P8 -> 9072.7962 | X8: 2005 | Y8: 5079639.3 | Z8: 3358448.9 | AA8: 634708 | AB8: =SUM(Y8:AA8) -> 9072796.2
C9: רבעון 2 | D9: =Y9/1000 -> 5398.7502 | J9: =Z9/1000 -> 3498.0922 | P9: =AA9/1000 -> 728.0158 | Q9: 56344.4 | R9: 549025 | S9: 76786 | T9: 5864 | U9: 104722 | V9: =D9+J9+P9 -> 9624.8582 | Y9: 5398750.2 | Z9: 3498092.2 | AA9: 728015.8 | AB9: =Y9+Z9+AA9 -> 9624858.2
C10: רבעון 3 | D10: =Y10/1000 -> 5645.1269 | E10: 3089236 | F10: 2562357.3 | G10: 3195645 | H10: 292895 | I10: 52355 | J10: =Z10/1000 -> 3807.277 | K10: 2220071.5 | L10: 1587205.5 | M10: 1408081.8 | N10: 154204 | O10: 19473 | P10: =AA10/1000 -> 477.067 | Q10: 65983 | R10: 458367 | S10: 84959 | T10: 6657 | U10: 136720 | V10: =D10+J10+P10 -> 9929.4709 | Y10: 5645126.9 | Z10: 3807277 | AA10: 477067 | AB10: =Y10+Z10+AA10 -> 9929470.9
C11: רבעון 4 | D11: =Y11/1000 -> 4867.1174 | E11: 2822765.5 | F11: 2044351.9 | G11: 2709864 | H11: 252258 | I11: 0 | J11: =Z11/1000 -> 3564.118 | K11: 2105005.5 | L11: 1459112 | M11: 1393744 | N11: 154871 | O11: 0 | P11: =AA11/1000 -> 653.994 | Q11: 57349 | R11: 387112 | S11: 62084 | T11: 5094 | U11: 75701 | V11: =D11+J11+P11 -> 9085.2294 | Y11: 4867117.4 | Z11: 3564118 | AA11: 653994 | AB11: =Y11+Z11+AA11 -> 9085229.4
C12: שנתי | D12: =Y12/1000 -> 0 | J12: =Z12/1000 -> 0 | P12: =AA12/1000 -> 0 | Q12: =SUM(Q8:Q11) -> 179676.4 | R12: =SUM(R8:R11) -> 1394504 | S12: =SUM(S8:S11) -> 223829 | T12: =SUM(T8:T11) -> 17615 | U12: =SUM(U8:U11) -> 317143
B13: 2004 | C13: רבעון 1 | D13: =Y13/1000 -> 5205.1331 | E13: 3100253.9 | F13: 2104879.2 | G13: 3005190 | H13: 276476 | I13: 37712 | J13: =Z13/1000 -> 3783.015 | K13: 2338847.3 | L13: 1444167.7 | M13: 1423029.5 | N13: 156437 | O13: 18 | P13: =AA13/1000 -> 600.2719 | Q13: 65813 | R13: 362023 | S13: 91110 | T13: 7097 | U13: 13798 | V13: =D13+J13+P13 -> 9588.42 | X13: 2004 | Y13: 5205133.1 | Z13: 3783015 | AA13: 600271.9 | AB13: =Y13+Z13+AA13 -> 9588420
C14: רבעון 2 | D14: =Y14/1000 -> 4851.0236 | E14: 3126090.7 | F14: 1724932.9 | G14: 2329003.1 | H14: 210021 | I14: 77749 | J14: =Z14/1000 -> 3478.8404 | K14: 2025951.1 | L14: 1452889.3 | M14: 1163886 | N14: 113302 | O14: 24 | P14: =AA14/1000 -> 525.562 | Q14: 77361 | R14: 479371 | S14: 80193 | T14: 6481 | U14: 0 | V14: =D14+J14+P14 -> 8855.426 | Y14: 4851023.6 | Z14: 3478840.4 | AA14: 525562 | AB14: =Y14+Z14+AA14 -> 8855426
C15: רבעון 3 | D15: =Y15/1000 -> 5481.1416 | E15: 3275479.5 | F15: 2205662.1 | G15: 3079847.7 | H15: 285339 | I15: 40835 | J15: =Z15/1000 -> 3707.2907 | K15: 2177769.4 | L15: 1529521.3 | M15: 1311836.7 | N15: 142827 | O15: 62 | P15: =AA15/1000 -> 556.732 | Q15: 99355 | R15: 426207 | S15: 131165 | T15: 10035 | U15: 0 | V15: =D15+J15+P15 -> 9745.1643 | Y15: 5481141.6 | Z15: 3707290.7 | AA15: 556732 | AB15: =Y15+Z15+AA15 -> 9745164.3
C16: רבעון 4 | D16: =Y16/1000 -> 5000.8363 | E16: 2836116.4 | F16: 2164719.9 | G16: 2738348.1 | H16: 259484 | I16: 3308 | J16: =Z16/1000 -> 3480.3854 | K16: 2185108.3 | L16: 1295277.1 | M16: 1257391.2 | N16: 132434 | O16: 38 | P16: =AA16/1000 -> 427.836 | Q16: 83487 | R16: 516784.9 | S16: 84200 | T16: 6238 | U16: 22 | V16: =D16+J16+P16 -> 8909.0577 | Y16: 5000836.3 | Z16: 3480385.4 | AA16: 427836 | AB16: =Y16+Z16+AA16 -> 8909057.7
C17: שנתי | D17: =Y17/1000 -> 0 | J17: =Z17/1000 -> 0 | P17: =AA17/1000 -> 0 | Q17: =SUM(Q13:Q16) -> 326016 | R17: =SUM(R13:R16) -> 1784385.9 | S17: =SUM(S13:S16) -> 386668 | T17: =SUM(T13:T16) -> 29851 | U17: =SUM(U13:U16) -> 13820 | V17: =SUM(D17:U17) -> 2540740.9 | AB17: =SUM(Y17:AA17) -> 0
B18: 2003 | C18: רבעון 1 | D18: =Y18/1000 -> 4683.5923 | E18: 2818946.1 | F18: 1864646.2 | G18: 2407368.1 | H18: 225328 | I18: 38993 | J18: =Z18/1000 -> 3278.9079 | K18: 2111714.9 | L18: 1167193 | M18: 1173272 | N18: 123809 | O18: 72 | P18: =AA18/1000 -> 444.461 | Q18: 53226 | R18: 600768 | S18: 59023 | T18: 4013 | U18: 0 | V18: =D18+J18+P18 -> 8406.9612 | X18: 2003 | Y18: 4683592.3 | Z18: 3278907.9 | AA18: 444461 | AB18: =Y18+Z18+AA18 -> 8406961.2
C19: רבעון 2 | D19: =Y19/1000 -> 5003.927 | E19: 2868868.9 | F19: 2135058.1 | G19: 3042312.2 | H19: 286849 | I19: 53132 | J19: =Z19/1000 -> 3787.2473 | K19: 2376759.8 | L19: 1410487.5 | M19: 1268728.7 | N19: 138940 | O19: 90 | P19: =AA19/1000 -> 524.35 | Q19: 82595 | R19: 394472 | S19: 79452 | T19: 5201 | U19: 0 | V19: =D19+J19+P19 -> 9315.5243 | Y19: 5003927 | Z19: 3787247.3 | AA19: 524350 | AB19: =Y19+Z19+AA19 -> 9315524.3
C20: רבעון 3 | D20: =Y20/1000 -> 4909.7535 | E20: 2653823.1 | F20: 2255930.4 | G20: 2834288 | H20: 265536 | I20: 22740 | J20: =Z20/1000 -> 3546.573 | K20: 2129332 | L20: 1417241 | M20: 1224634 | N20: 129144 | O20: 44 | P20: =AA20/1000 -> 605.3694 | V20: =D20+J20+P20 -> 9061.6959 | Y20: 4909753.5 | Z20: 3546573 | AA20: 605369.4 | AB20: =Y20+Z20+AA20 -> 9061695.9
C21: רבעון 4 | D21: =Y21/1000 -> 4207.6981 | E21: 2433726.6 | F21: 1773971.5 | G21: 2348141 | H21: 236123 | I21: 172 | J21: =Z21/1000 -> 3449.5672 | K21: 2267591.7 | L21: 1181975.5 | M21: 1212655 | N21: 122384 | O21: 25 | P21: =AA21/1000 -> 530.1707 | V21: =D21+J21+P21 -> 8187.436 | Y21: 4207698.1 | Z21: 3449567.2 | AA21: 530170.7 | AB21: =Y21+Z21+AA21 -> 8187436
C22: שנתי
K28: =SUM(#REF!) -> #REF! | N28: =SUM(#REF!) -> #REF! | Y28: נמל חיפה: סה"כ פריקה וטעינה | Z28: נמל אשדוד: סה"כ פריקה וטעינה | AA28: נמל אילת: סה"כ פריקה וטעינה | AB28: סה"כ
E29: =SUM(#REF!) -> #REF! | H29: =SUM(#REF!) -> #REF! | K29: =SUM(#REF!) -> #REF! | N29: =SUM(#REF!) -> #REF! | Y29: 5079.6393 | Z29: 3356.3899 | AA29: 595.046 | AB29: 9031.0752
J30: Q4- 2005 | P30: Q1- 2003 | Y30: 5381.0544 | Z30: 3498.0772 | AA30: 701.4478 | AB30: 9580.5794
J31: Q3- 2005 | N31: =SUM(#REF!) -> #REF! | P31: Q2- 2003 | Y31: 5651.593 | Z31: 3807.277 | AA31: 477.067 | AB31: 9935.937
E32: =SUM(#REF!) -> #REF! | H32: =SUM(#REF!) -> #REF! | J32: Q2- 2005 | P32: Q3- 2003 | Y32: 4867.118 | Z32: 3564.117 | AA32: 653.994 | AB32: 9085.229
J33: Q1- 2005 | P33: Q4- 2003 | Y33: 5205.1331 | Z33: 3783.015 | AA33: 600.2719 | AB33: 9588.42
J34: Q4- 2004 | P34: Q1- 2004 | Y34: 4851.0236 | Z34: 3478.8404 | AA34: 525.562 | AB34: 8855.426
J35: Q3- 2004 | P35: Q2- 2004 | Y35: 5481.1416 | Z35: 3707.2907 | AA35: 556.732 | AB35: 9745.1643
J36: Q2- 2004 | P36: Q3- 2004 | Y36: 5000.8363 | Z36: 3480.3854 | AA36: 427.836 | AB36: 8909.0577
J37: Q1- 2004 | P37: Q4- 2004 | Y37: 4683.5923 | Z37: 3278.9079 | AA37: 444.461 | AB37: 8406.9612
J38: Q4- 2003 | P38: Q1- 2005 | Y38: 5003.927 | Z38: 3787.2473 | AA38: 524.35 | AB38: 9315.5243
J39: Q3- 2003 | P39: Q2- 2005 | Y39: 4909.7535 | Z39: 3546.573 | AA39: 605.3694 | AB39: 9061.6959
J40: Q2- 2003 | P40: Q3- 2005 | Y40: 4207.6981 | Z40: 3449.5672 | AA40: 530.1707 | AB40: 8187.436
J41: Q1- 2003 | P41: Q4- 2005
D55: נמל חיפה | J55: נמל אשדוד | P55: נמל אילת
B56: 2005 | C56: רבעון 1
C57: רבעון 2
C58: רבעון 3 | D58: 5651593 | E58: 3089236 | F58: 2562357.3 | G58: 3195645 | H58: 292895 | I58: 52355 | J58: 3807277 | K58: 2220071.5 | L58: 1587205.5 | M58: 1408081.8 | N58: 154204 | O58: 19473 | P58: 477067
C59: רבעון 4 | D59: 4867118 | E59: 2822765.5 | F59: 2044351.9 | G59: 2709864 | H59: 252258 | I59: 0 | J59: 3564117 | K59: 2105005.5 | L59: 1459112 | M59: 1393744 | N59: 154871 | O59: 0 | P59: 653994
C60: שנתי
B61: 2004 | C61: רבעון 1 | D61: 5205133.1 | E61: 3100253.9 | F61: 2104879.2 | G61: 3005190 | H61: 276476 | I61: 37712 | J61: 3783015 | K61: 2338847.3 | L61: 1444167.7 | M61: 1423029.5 | N61: 156437 | O61: 18 | P61: 600271.9
C62: רבעון 2 | D62: 4851023.6 | E62: 3126090.7 | F62: 1724932.9 | G62: 2329003.1 | H62: 210021 | I62: 77749 | J62: 3478840.4 | K62: 2025951.1 | L62: 1452889.3 | M62: 1163886 | N62: 113302 | O62: 24 | P62: 525562
...

Sheet גיליון3
Q3: מרחב נמל חיפה Haifa Port Erea | W3: מרחב נמל אשדוד Ashdod Port Erea | Z3: נמל אילת Eilat Port
B4: תחום נמל חיפה Haifa port | C4: נמל המפרץ SIPG | D4: נמל מספנות ישראל Israel shipyards | E4: תחום נמל אשדוד Ashdod port | F4: נמל הדרום HCT | G4: נמל אילת Eilat port | H4: כל הנמלים Total ports | K4: נמל חיפה Haifa port | L4: נמל אשדוד Ashdod port | M4: נמל אילת Eilat port | N4: מספנות ישראל Israel shipyards | O4: כל הנמלים Total ports | P4: רבעון | Q4: ח.נמל חיפה | R4: דגון | S4: דלק | T4: כימיקלים | U4: נמל המפרץ | V4: נמל מספנות | W4: ח.נמל אשדוד | X4: נמל הדרום | Y4: דלק | Z4: ח.נ אילת
A5: Q1-2004 | B5: 5000.8363 | C5: SIPG | E5: 3480.3854 | G5: 427.836 | H5: 8909.0577 | J5: Q1-2004 | K5: 5000.8363 | L5: 3480.3854 | M5: 427.836 | O5: 8909.0577 | P5: Query | Q5: Haifa | R5: Dagon | S5: Fuel | T5: Chemical | U5: SIPG | V5: shipyards | W5: Ashdod | X5: HCT | Y5: Fuel | Z5: Eilat
A6: Q2-2004 | B6: 5481.1416 | E6: 3707.2907 | G6: 556.732 | H6: 9745.1643 | J6: Q2-2004 | K6: 5481.1416 | L6: 3707.2907 | M6: 556.732 | O6: 9745.1643
A7: Q3-2004 | B7: 4851.0236 | E7: 3478.8404 | G7: 525.562 | H7: 8855.426 | J7: Q3-2004 | K7: 4851.0236 | L7: 3478.8404 | M7: 525.562 | O7: 8855.426
A8: Q4-2004 | B8: 5205.1331 | E8: 3783.015 | G8: 600.2719 | H8: 9588.42 | J8: Q4-2004 | K8: 5205.1331 | L8: 3783.015 | M8: 600.2719 | O8: 9588.42
A9: Q1-2005 | B9: 4867.1175 | E9: 3564.118 | G9: 653.994 | H9: 9085.2295 | J9: Q1-2005 | K9: 4867.1175 | L9: 3564.118 | M9: 653.994 | O9: 9085.2295
A10: Q2-2005 | B10: 5645.127 | E10: 3807.278 | G10: 477.067 | H10: 9929.472 | J10: Q2-2005 | K10: 5645.127 | L10: 3807.278 | M10: 477.067 | O10: 9929.472
A11: Q3-2005 | B11: 5398.75 | E11: 3498.093 | G11: 728.321 | H11: 9625.164 | J11: Q3-2005 | K11: 5398.75 | L11: 3498.093 | M11: 728.321 | O11: 9625.164
A12: Q4-2005 | B12: 5079.639 | E12: 3358.449 | G12: 634.695 | H12: 9072.783 | J12: Q4-2005 | K12: 5079.639 | L12: 3358.449 | M12: 634.695 | O12: 9072.783
A13: Q1-2006 | B13: 4941 | E13: 3412 | G13: 302.335 | H13: 8654.335 | J13: Q1-2006 | K13: 4941 | L13: 3412 | M13: 302.335 | O13: 8654.335
A14: Q2-2006 | B14: 5525 | E14: 3668 | G14: 435 | H14: =SUM(B14:G14) -> 9628 | J14: Q2-2006 | K14: 5525 | L14: 3668 | M14: 435 | O14: =SUM(K14:M14) -> 9628
A15: Q3-2006 | B15: 3934 | E15: 4270 | G15: 449 | H15: =SUM(B15:G15) -> 8653 | J15: Q3-2006 | K15: 3934 | L15: 4270 | M15: 449 | O15: =SUM(K15:M15) -> 8653
A16: Q4-2006 | B16: 4802 | E16: 3794 | G16: 722 | H16: 9318 | J16: Q4-2006 | K16: 4802 | L16: 3794 | M16: 722 | O16: 9318
A17: Q1-2007 | B17: 5197.724 | E17: 3672.378 | G17: 559.324 | H17: =SUM(B17:G17) -> 9429.426 | J17: Q1-2007 | K17: 5197.724 | L17: 3672.378 | M17: 559.324 | O17: =SUM(K17:M17) -> 9429.426
A18: Q2-2007 | B18: 5308.923 | E18: 4157.771 | G18: 559.938 | H18: =SUM(B18:G18) -> 10026.632 | J18: Q2-2007 | K18: 5308.923 | L18: 4157.771 | M18: 559.938 | O18: =SUM(K18:M18) -> 10026.632
A19: Q3-2007 | B19: 5270.617 | E19: 3986.189 | G19: 746.757 | H19: =SUM(B19:G19) -> 10003.563 | J19: Q3-2007 | K19: 5270.617 | L19: 3986.189 | M19: 746.757 | O19: =SUM(K19:M19) -> 10003.563
A20: Q4-2007 | B20: 5679.677 | E20: 4415.527 | G20: 669.198 | H20: =SUM(B20:G20) -> 10764.402 | J20: Q4-2007 | K20: 5679.677 | L20: 4415.527 | M20: 669.198 | O20: =SUM(K20:M20) -> 10764.402
A21: Q1-2008 | B21: 5932.894 | E21: 4230.756 | G21: 727.918 | H21: =SUM(B21:G21) -> 10891.568 | J21: Q1-2008 | K21: 5932.894 | L21: 4230.756 | M21: 727.918 | O21: =SUM(K21:M21) -> 10891.568
A22: Q2-2008 | B22: 6243.29 | E22: 4248.426 | G22: 472.83 | H22: =SUM(B22:G22) -> 10964.546 | J22: Q2-2008 | K22: 6243.29 | L22: 4248.426 | M22: 472.83 | O22: =SUM(K22:M22) -> 10964.546
A23: Q3-2008 | B23: 5249.754 | E23: 3821.693 | G23: 682.723 | H23: =SUM(B23:G23) -> 9754.17 | J23: Q3-2008 | K23: 5249.754 | L23: 3821.693 | M23: 682.723 | O23: =SUM(K23:M23) -> 9754.17
A24: Q4-2008 | B24: 5138.933 | E24: 3550.646 | G24: 441.447 | H24: =SUM(B24:G24) -> 9131.026 | J24: Q4-2008 | K24: 5138.933 | L24: 3550.646 | M24: 441.447 | O24: =SUM(K24:M24) -> 9131.026
A25: Q1-2009 | B25: 4573.254 | D25: 102.202 | E25: 3087.887 | G25: 298.899 | H25: =SUM(B25:G25) -> 8062.242 | J25: 2008 | K25: =SUM(K21:K24) -> 22564.871 | L25: =SUM(L21:L24) -> 15851.521 | M25: =SUM(M21:M24) -> 2324.918 | N25: =SUM(N21:N24) -> 0 | O25: =SUM(O21:O24) -> 40741.31
A26: Q2-2009 | B26: 5271.534 | D26: 130.98 | E26: 3609.244 | G26: 348.786 | H26: =SUM(B26:G26) -> 9360.544 | J26: Q1-2009 | K26: 4573.254 | L26: 3087.887 | M26: 298.899 | N26: 102.202 | O26: =SUM(K26:N26) -> 8062.242
A27: Q3-2009 | B27: 4966.495 | D27: 118 | E27: 4168.89 | G27: 473.555 | H27: =SUM(B27:G27) -> 9726.94 | J27: Q2-2009 | K27: 5271.534 | L27: 3609.244 | M27: 348.786 | N27: 130.98 | O27: =SUM(K27:N27) -> 9360.544
A28: Q4-2009 | B28: 5001.509 | D28: 104.5997 | E28: 4049.247 | G28: 637.993 | H28: =SUM(B28:G28) -> 9793.3487 | J28: Q3-2009 | K28: 4966.495 | L28: 4168.89 | M28: 473.555 | N28: 118 | O28: =SUM(K28:N28) -> 9726.94
A29: Q1-2010 | B29: 5245.232 | D29: 126.14747 | E29: 4672.874 | G29: 591.856 | H29: =SUM(B29:G29) -> 10636.109 | J29: Q4-2009 | K29: 5001.509 | L29: 4049.247 | M29: 637.993 | N29: 104.5997 | O29: =SUM(K29:N29) -> 9793.3487
A30: Q2-2010 | B30: 5716.708 | D30: 193.69482 | E30: 4928.889 | G30: 627.53 | H30: =SUM(B30:G30) -> 11466.822 | J30: 2009 | K30: =SUM(K26:K29) -> 19812.792 | L30: =SUM(L26:L29) -> 14915.268 | M30: =SUM(M26:M29) -> 1759.233 | N30: =SUM(N26:N29) -> 455.7817 | O30: =SUM(O26:O29) -> 36943.075
A31: Q3-2010 | B31: 5701.966 | D31: 171.15493 | E31: 4235.003 | G31: 544.342 | H31: =SUM(B31:G31) -> 10652.466 | J31: Q1-2010 | K31: 5245.232 | L31: 4672.874 | M31: 591.856 | N31: 126.14747 | O31: =SUM(K31:N31) -> 10636.109
A32: Q4-2010 | B32: 5173.5724 | D32: 228.06077 | E32: 4697.771 | G32: 557.28 | H32: =SUM(B32:G32) -> 10656.684 | J32: Q2-2010 | K32: 5716.708 | L32: 4928.889 | M32: 627.53 | N32: 193.69482 | O32: =SUM(K32:N32) -> 11466.822
A33: Q1-2011 | B33: 5343.2321 | D33: 237.623 | E33: 4967.7328 | G33: 452.9712 | H33: =SUM(B33:G33) -> 11001.559 | J33: Q3-2010 | K33: 5701.966 | L33: 4235.003 | M33: 544.342 | N33: 171.15493 | O33: =SUM(K33:N33) -> 10652.466
A34: Q2-2011 | B34: 6067.2985 | D34: 273.411 | E34: 4859.1285 | G34: 532.4587 | H34: =SUM(B34:G34) -> 11732.297 | J34: Q4-2010 | K34: 5173.5724 | L34: 4697.771 | M34: 557.28 | N34: 228.06077 | O34: =SUM(K34:N34) -> 10656.684
A35: Q3-2011 | B35: 5644.5212 | D35: 256.752 | E35: 4793.3821 | G35: 652.937 | H35: =SUM(B35:G35) -> 11347.592 | J35: 2010 | K35: =SUM(K31:K34) -> 21837.478 | L35: =SUM(L31:L34) -> 18534.537 | M35: =SUM(M31:M34) -> 2321.008 | N35: =SUM(N31:N34) -> 719.05799 | O35: =SUM(O31:O34) -> 43412.081
A36: Q4-2011 | B36: 5497.1891 | D36: 257.574 | E36: 4595.1904 | G36: 642.078 | H36: =SUM(B36:G36) -> 10992.031 | J36: Q1-2011 | K36: 5354.0801 | L36: 4969.7108 | M36: 452.9712 | N36: 237.623 | O36: =SUM(K36:N36) -> 11014.385
A37: Q1-2012 | B37: 5951.1769 | D37: 299.489 | E37: 4582.4339 | G37: 357.325 | H37: =SUM(B37:G37) -> 11190.425 | J37: Q2-2011 | K37: 6070.6425 | L37: 4859.2669 | M37: 532.4587 | N37: 273.411 | O37: =SUM(K37:N37) -> 11735.779
A38: Q2-2012 | B38: 6251.0907 | D38: 343.513 | E38: 5323.9772 | G38: 500.579 | H38: =SUM(B38:G38) -> 12419.16 | J38: Q3-2011 | K38: 5649.5392 | L38: 4770.7561 | M38: 652.937 | N38: 256.752 | O38: =SUM(K38:N38) -> 11329.984
A39: Q3-2012 | B39: 5899.2427 | D39: 348.453 | E39: 5200.2986 | G39: 420.372 | H39: =SUM(B39:G39) -> 11868.366 | J39: Q4-2011 | K39: 5497.1896 | L39: 4468.3115 | M39: 642.078 | N39: 257.574 | O39: =SUM(K39:N39) -> 10865.153
A40: Q4-2012 | B40: 5886.9419 | D40: 310.819 | E40: 4507.7047 | G40: 283.503 | H40: =SUM(B40:G40) -> 10988.969 | J40: 2011 | K40: =SUM(K36:K39) -> 22571.451 | L40: =SUM(L36:L39) -> 19068.045 | M40: =SUM(M36:M39) -> 2280.4449 | N40: =SUM(N36:N39) -> 1025.36 | O40: =SUM(O36:O39) -> 44945.302
A41: Q1-2013 | B41: ='סה"כ מטענים - טבלה '!N139 -> 6513.6543 | D41: 363.707 | E41: ='סה"כ מטענים - טבלה '!M139 -> 4606.0101 | G41: ='סה"כ מטענים - טבלה '!L139 -> 464.6754 | H41: =SUM(B41:G41) -> 11948.047 | J41: Q1-2012 | K41: 5951.1769 | L41: 4582.4339 | M41: 357.325 | N41: 299.489 | O41: =SUM(K41:N41) -> 11190.425
A42: Q2-2013 | B42: ='סה"כ מטענים - טבלה '!N143 -> 7021.2679 | D42: ='סה"כ מטענים - טבלה '!G143 -> 39.92269 | E42: ='סה"כ מטענים - טבלה '!M143 -> 5280.8146 | G42: 671.202 | H42: =SUM(B42:G42) -> 13013.207 | J42: Q2-2012 | K42: 6251.0907 | L42: 5323.9772 | M42: 500.579 | N42: 343.513 | O42: =SUM(K42:N42) -> 12419.16
...

Sheet סה"כ תנועת מטענים - טבלה
A1: Ministry Of Transport - Administration of Shipping & Ports | M1: משרד התחבורה - רשות הספנות והנמלים
A2: Economics and International Affairs Division | M2: אגף כלכלה וקשרי חוץ
A3: TABLE 1 : Total Traffic Cargo in Israeli Ports | M3: לוח 1: סה"כ תנועת מטענים בנמלי ישראל
A4: Thousand tons | M4: אלפי טונות
A5: נמל אילת | D5: מרחב נמל אשדוד | J5: מרחב נמל חיפה | K5: סהכ תנועות
A6: Eilat Port | B6: Ashdod Port Erea | E6: Haifa Port Erea | K6: Total Traffic
A7: ח.נ אילת | B7: דלק אשדוד | C7: נמל הדרום | D7: ח.נמל אשדוד | E7: מספנות ישראל | F7: נמל המפרץ | G7: כימיקלים | H7: דלק תש"ן | I7: דגון | J7: ח.נמל חיפה | L7: חודשים | M7: שנה
A8: Eilat | B8: Fuel Ashdod | C8: HCT | D8: Ashdod | E8: shipyards | F8: SIPG | G8: Chemical | H8: Fuel PEI | I8: Dagon | J8: Haifa | L8: months | M8: Year
A9: 1799 | D9: 15758 | J9: 18534 | K9: 36091 | M9: 2000
A10: 1696 | D10: 13630 | J10: 16731 | K10: 32057 | M10: 2001
A11: 1613 | D11: 14722 | J11: 17073 | K11: 33408 | M11: 2002
A12: 1995.4318 | D12: 14062.295 | J12: 18804.971 | K12: 34971.617 | M12: 2003
A13: 2110.4019 | D13: 14449.531 | J13: 20538.135 | K13: 37098.068 | M13: 2004
A14: 2494.077 | D14: 14227.938 | J14: 20990.633 | K14: 37712.648 | M14: 2005
A15: 1908.335 | D15: 15144 | J15: 19202 | K15: 36253.335 | M15: 2006
A16: 2534.679 | D16: 16231.865 | J16: 21456.941 | K16: 40223.485 | M16: 2007
A17: 2577.268 | D17: 15851.521 | E17: 232.33588 | J17: 22560.377 | K17: 40989.166 | M17: 2008
A18: 1759.233 | D18: 14915.267 | E18: 455.9027 | J18: 19812.792 | K18: 36943.195 | M18: 2009
A19: 2321.008 | D19: 18535.004 | E19: 719.05799 | J19: 21837.478 | K19: 43412.548 | M19: 2010
A20: 2280.4449 | D20: 19215.434 | E20: 1025.3604 | J20: 22552.241 | K20: 45073.48 | M20: 2011
A21: 1561.779 | D21: 19614.414 | E21: 1302.274 | J21: 23988.116 | K21: 46466.584 | M21: 2012
A22: 2081.9277 | D22: 19213.56 | E22: 1666.892 | J22: 25787.838 | K22: 48750.218 | M22: 2013
A23: 2310.219 | D23: 21554.739 | E23: 1930.758 | J23: 27500.157 | K23: 53295.873 | M23: 2014
A24: 2103.1847 | D24: 22273.485 | E24: 2135.813 | J24: 27259.427 | K24: 53771.91 | M24: 2015
A25: 2109.4163 | D25: 24086.418 | E25: 2825.522 | J25: 28026.57 | K25: 57047.926 | M25: 2016
A26: 2171.4551 | D26: 23584.549 | E26: 2928.2534 | J26: 29251.804 | K26: 57936.062 | M26: 2017
A27: 2290.065 | D27: 23475.047 | E27: 3418.822 | J27: 29531.032 | K27: 58714.966 | M27: 2018
A28: 1944.7171 | D28: 23589.92 | E28: 3074.337 | J28: 29084.266 | K28: 57693.241 | M28: 2019
A29: 2224.571 | D29: 23973.646 | E29: 4456.5525 | J29: 26797.954 | K29: 57452.724 | M29: 2020
A30: =A275+A279+A283+A287 -> 1843.0539 | B30: =B275+B279+B283+B287 -> 898.86152 | C30: =C275+C279+C283+C287 -> 48.8156 | D30: =D275+D279+D283+D287 -> 23587.757 | E30: =E275+E279+E283+E287 -> 4805.6542 | F30: =F275+F279+F283+F287 -> 75.215 | G30: =G275+G279+G283+G287 -> 821.793 | H30: =H275+H279+H283+H287 -> 6624.5927 | ... K30: =K275+K279+K283+K287 -> 59764.339 | M30: 2021
A31: =A292+A296+A300+A304 -> 1855.0794 | B31: =B292+B296+B300+B304 -> 1094.7029 | C31: =C292+C296+C300+C304 -> 1205.1391 | D31: =D292+D296+D300+D304 -> 21734.585 | E31: =E292+E296+E300+E304 -> 4456.614 | F31: =F292+F296+F300+F304 -> 3904.8639 | G31: =G292+G296+G300+G304 -> 863.951 | H31: =H292+H296+H300+H304 -> 7876.3558 | ... K31: =K292+K296+K300+K304 -> 60713.253 | M31: 2022
A32: =A309+A313+A317+A321 -> 1862.338 | B32: =B309+B313+B317+B321 -> 1122.7401 | C32: =C309+C313+C317+C321 -> 4282.4016 | D32: =D309+D313+D317+D321 -> 19000.532 | E32: =E309+E313+E317+E321 -> 3698.092 | F32: =F309+F313+F317+F321 -> 8589.297 | G32: =G309+G313+G317+G321 -> 843.696 | H32: =H309+H313+H317+H321 -> 7140.3348 | ... K32: =K309+K313+K317+K321 -> 60665.479 | M32: 2023
A33: =A326+A330+A334+A338 -> 668.841 | B33: =B326+B330+B334+B338 -> 754.70234 | C33: =C326+C330+C334+C338 -> 5851.7868 | D33: =D326+D330+D334+D338 -> 19699.602 | E33: =E326+E330+E334+E338 -> 3388.7849 | F33: =F326+F330+F334+F338 -> 5249.5871 | G33: =G326+G330+G334+G338 -> 664.941 | H33: =H326+H330+H334+H338 -> 5779.2244 | ... K33: =K326+K330+K334+K338 -> 54322.656 | M33: 2024
A34: =A343+A347+A348+A349 -> 320.219 | B34: =B343+B347+B348+B349 -> 559.27564 | C34: =C343+C347+C348+C349 -> 4632.5953 | D34: =D343+D347+D348+D349 -> 13949.19 | E34: =E343+E347+E348+E349 -> 2179.0177 | F34: =F343+F347+F348+F349 -> 3814.064 | G34: =G343+G347+G348+G349 -> 387.236 | H34: =H343+H347+H348+H349 -> 2390.0027 | ... K34: =K343+K347+K348+K349 -> 37347.082 | L34: 01-08 | M34: 2025
A36: 653.994 | D36: 3564.118 | J36: 4867.1175 | K36: 9085.2295 | L36: 01-03 | M36: 2005
A37: 477.067 | D37: 3807.278 | J37: 5645.127 | K37: 9929.472 | L37: 04-06
A38: 728.321 | D38: 3498.093 | J38: 5398.75 | K38: 9625.164 | L38: 07-09
A39: 634.695 | D39: 3358.449 | J39: 5079.639 | K39: 9072.783 | L39: 10-12
A41: 302.335 | D41: 3412 | J41: 4941 | K41: 8654.335 | L41: 01-03 | M41: 2006
A42: 435 | D42: 3668 | J42: 5525 | K42: 9628 | L42: 04-06
...

Sheet סה"כ פריקת מטענים - טבלה 
A1: Ministry Of Transport - Administration of Shipping & Ports | M1: משרד התחבורה - רשות הספנות והנמלים
A2: Economics and International Affairs Division | M2: אגף כלכלה וקשרי חוץ
A3: TABLE 1 : Total Discharge Cargo in Israeli Ports | M3: לוח 1 : סה"כ פריקת מטענים בנמלי ישראל
A4: Thousand tons | M4: אלפי טונות
A5: נמל אילת | D5: מרחב נמל אשדוד | J5: מרחב נמל חיפה | K5: סהכ פריקה
A6: Eilat Port | B6: Ashdod Port Erea | E6: Haifa Port Erea | K6: Total Discharge
A7: ח.נ אילת | B7: דלק אשדוד | C7: נמל הדרום | D7: ח.נמל אשדוד | E7: מספנות ישראל | F7: נמל המפרץ | G7: כימיקלים | H7: דלק תש"ן | I7: דגון | J7: ח.נמל חיפה | L7: חודשים | M7: שנה
A8: Eilat | B8: Fuel Ashdod | C8: HCT | D8: Ashdod | E8: shipyards | F8: SIPG | G8: Chemical | H8: Fuel PEI | I8: Dagon | J8: Haifa | L8: months | M8: Year
A9: 254 | D9: 10499 | J9: 11472 | K9: =J9+D9+A9 -> 22225 | M9: 2000
A10: 258 | D10: 8389 | J10: 10072 | K10: =J10+D10+A10 -> 18719 | M10: 2001
A11: 200 | D11: 9250 | J11: 10094 | K11: =J11+D11+A11 -> 19544 | M11: 2002
A12: 234.9648 | D12: 8885.3984 | J12: 10775.365 | K12: =J12+D12+A12 -> 19895.728 | M12: 2003
A13: 326.016 | D13: 8727.6761 | J13: 12337.941 | K13: =J13+D13+A13 -> 21391.633 | M13: 2004
A14: =SUM(A36:A39) -> 291.321 | D14: =SUM(D36:D39) -> 8874.972 | J14: =SUM(J36:J39) -> 11911.177 | K14: =J14+D14+A14 -> 21077.47 | M14: 2005
A15: 269 | D15: 9626 | J15: 10508 | K15: =J15+D15+A15 -> 20403 | M15: 2006
A16: =SUM(A46:A49) -> 224.99 | D16: =SUM(D46:D49) -> 10105.497 | J16: =SUM(J46:J49) -> 12145.549 | K16: =J16+D16+A16 -> 22476.036 | M16: 2007
A17: =A54+A58+A62+A66 -> 220.335 | D17: =D54+D58+D62+D66 -> 10047.229 | E17: 232.33588 | J17: =J54+J58+J62+J66 -> 12589.633 | K17: =J17+E17+D17+A17 -> 23089.533 | M17: 2008
A18: =A71+A75+A79+A83 -> 173.582 | D18: =D71+D75+D79+D83 -> 9997.253 | E18: =E71+E75+E79+E83 -> 436.4007 | J18: =J71+J75+J79+J83 -> 10937.204 | K18: =J18+E18+D18+A18 -> 21544.44 | M18: 2009
A19: =A88+A92+A96+A100 -> 66.271 | D19: =D88+D92+D96+D100 -> 11227.143 | E19: =E88+E92+E96+E100 -> 709.82099 | J19: =J88+J92+J96+J100 -> 12140.031 | K19: =J19+E19+D19+A19 -> 24143.266 | M19: 2010
A20: =A105+A109+A113+A117 -> 161.1249 | D20: =D105+D109+D113+D117 -> 11990.761 | E20: =E105+E109+E113+E117 -> 1000.7894 | J20: =J105+J109+J113+J117 -> 12330.989 | K20: =J20+E20+D20+A20 -> 25483.664 | M20: 2011
A21: =A122+A126+A130+A134 -> 105.57 | D21: =D122+D126+D130+D134 -> 12382.74 | E21: =E122+E126+E130+E134 -> 1270.11 | J21: =J122+J126+J130+J134 -> 13278.68 | K21: =J21+E21+D21+A21 -> 27037.101 | M21: 2012
A22: =A139+A143+A147+A151 -> 160.61696 | D22: =D139+D143+D147+D151 -> 12384.553 | E22: =E139+E143+E147+E151 -> 1655.099 | J22: =J139+J143+J147+J151 -> 14086.853 | K22: =J22+E22+D22+A22 -> 28287.121 | M22: 2013
A23: =A156+A160+A164+A168 -> 184.1447 | D23: =D156+D160+D164+D168 -> 13290.384 | E23: =E156+E160+E164+E168 -> 1913.903 | J23: =J156+J160+J164+J168 -> 16623.139 | K23: =J23+E23+D23+A23 -> 32011.57 | M23: 2014
A24: =A173+A177+A181+A185 -> 211.91207 | D24: =D173+D177+D181+D185 -> 14324.833 | E24: =E173+E177+E181+E185 -> 2130.103 | J24: =J173+J177+J181+J185 -> 16932.104 | K24: =J24+E24+D24+A24 -> 33598.952 | M24: 2015
A25: =A190+A194+A198+A202 -> 218.293 | D25: =D190+D194+D198+D202 -> 15392.293 | E25: =E190+E194+E198+E202 -> 2823.185 | J25: =J190+J194+J198+J202 -> 17876.584 | K25: =J25+E25+D25+A25 -> 36310.356 | M25: 2016
A26: =A207+A211+A215+A219 -> 153.34512 | D26: =D207+D211+D215+D219 -> 15209.327 | E26: =E207+E211+E215+E219 -> 2928.1174 | J26: =J207+J211+J215+J219 -> 19139.522 | K26: =J26+E26+D26+A26 -> 37430.311 | M26: 2017
A27: =A224+A228+A232+A236 -> 175.799 | D27: =D224+D228+D232+D236 -> 15772.47 | E27: =E224+E228+E232+E236 -> 3416.685 | J27: =J224+J228+J232+J236 -> 19116.754 | K27: =J27+E27+D27+A27 -> 38481.708 | M27: 2018
A28: =A241+A245+A249+A253 -> 193.747 | D28: =D241+D245+D249+D253 -> 15838.642 | E28: =E241+E245+E249+E253 -> 3074.337 | J28: =J241+J245+J249+J253 -> 18976.427 | K28: =J28+E28+D28+A28 -> 38083.153 | M28: 2019
A29: =A258+A262+A266+A270 -> 149.168 | D29: =D258+D262+D266+D270 -> 16065.036 | E29: =E258+E262+E266+E270 -> 4456.5525 | J29: =J258+J262+J266+J270 -> 17658.561 | K29: =J29+E29+D29+A29 -> 38329.318 | M29: 2020
A30: =A275+A279+A283+A287 -> 210.6589 | B30: =B275+B279+B283+B287 -> 87.328206 | C30: =C275+C279+C283+C287 -> 0 | D30: =D275+D279+D283+D287 -> 16220.35 | E30: =E275+E279+E283+E287 -> 4805.6542 | F30: =F275+F279+F283+F287 -> 4.48 | G30: =G275+G279+G283+G287 -> 448.139 | H30: =H275+H279+H283+H287 -> 3311.9168 | ... K30: =K275+K279+K283+K287 -> 40624.043 | M30: 2021
A31: =A292+A296+A300+A304 -> 308.1324 | B31: =B292+B296+B300+B304 -> 237.3104 | C31: =C292+C296+C300+C304 -> 937.9179 | D31: =D292+D296+D300+D304 -> 14766.205 | E31: =E292+E296+E300+E304 -> 4456.614 | F31: =F292+F296+F300+F304 -> 2450.8953 | G31: =G292+G296+G300+G304 -> 420.474 | H31: =H292+H296+H300+H304 -> 4459.8742 | ... K31: =K292+K296+K300+K304 -> 41466.58 | M31: 2022
A32: =A309+A313+A317+A321 -> 279.718 | B32: =B309+B313+B317+B321 -> 71.964677 | C32: =C309+C313+C317+C321 -> 3354.3896 | D32: =D309+D313+D317+D321 -> 12641.866 | E32: =E309+E313+E317+E321 -> 3697.701 | F32: =F309+F313+F317+F321 -> 4807.0037 | G32: =G309+G313+G317+G321 -> 413.623 | H32: =H309+H313+H317+H321 -> 4366.1267 | ... K32: =K309+K313+K317+K321 -> 40987.632 | M32: 2023
A33: =A326+A330+A334+A338 -> 25.461 | B33: =B326+B330+B334+B338 -> 62.756288 | C33: =C326+C330+C334+C338 -> 4171.1275 | D33: =D326+D330+D334+D338 -> 12742.149 | E33: =E326+E330+E334+E338 -> 3388.7849 | F33: =F326+F330+F334+F338 -> 3117.8812 | G33: =G326+G330+G334+G338 -> 302.136 | H33: =H326+H330+H334+H338 -> 3343.8513 | ... K33: =K326+K330+K334+K338 -> 36942.536 | M33: 2024
A34: =A343+A347+A348+A349 -> 0 | B34: =B343+B347+B348+B349 -> 32.856242 | C34: =C343+C347+C348+C349 -> 3416.1395 | D34: =D343+D347+D348+D349 -> 9315.2181 | E34: =E343+E347+E348+E349 -> 2179.0177 | F34: =F343+F347+F348+F349 -> 2366.5825 | G34: =G343+G347+G348+G349 -> 183.211 | H34: =H343+H347+H348+H349 -> 1449.2199 | ... K34: =K343+K347+K348+K349 -> 26342.116 | L34: 01-08 | M34: 2025
A36: 53.226 | D36: 2105.006 | J36: 2822.7655 | K36: =J36+D36+A36 -> 4980.9975 | L36: 01-03 | M36: 2005
A37: 85.207 | D37: 2220.072 | J37: 3087.518 | K37: =J37+D37+A37 -> 5392.797 | L37: 04-06
A38: 76.459 | D38: 2304.379 | J38: 3041.695 | K38: =J38+D38+A38 -> 5422.533 | L38: 07-09
A39: 76.429 | D39: 2245.515 | J39: 2959.199 | K39: =J39+D39+A39 -> 5281.143 | L39: 10-12
A41: 49 | D41: 2240 | J41: 2719 | K41: =J41+D41+A41 -> 5008 | L41: 01-03 | M41: 2006
A42: 79 | D42: 2374 | J42: 2837 | K42: =J42+D42+A42 -> 5290 | L42: 04-06
...

Sheet סה"כ טעינת מטענים - טבלה
A1: Ministry Of Transport - Administration of Shipping & Ports | M1: משרד התחבורה - רשות הספנות והנמלים
A2: Economics and International Affairs Division | M2: אגף כלכלה וקשרי חוץ
A3: TABLE 1 : Total Charge Cargo in Israeli Ports | M3: לוח 1 : סה"כ טעינת מטענים בנמלי ישראל
A4: Thousand tons | M4: אלפי טונות
A5: נמל אילת | D5: מרחב נמל אשדוד | J5: מרחב נמל חיפה | K5: סהכ טעינה
A6: Eilat Port | B6: Ashdod Port Erea | E6: Haifa Port Erea | K6: Total Charge
A7: ח.נ אילת | B7: דלק אשדוד | C7: נמל הדרום | D7: ח.נמל אשדוד | E7: מספנות ישראל | F7: נמל המפרץ | G7: כימיקלים | H7: דלק תש"ן | I7: דגון | J7: ח.נמל חיפה | L7: חודשים | M7: שנה
A8: Eilat | B8: Fuel Ashdod | C8: HCT | D8: Ashdod | E8: shipyards | F8: SIPG | G8: Chemical | H8: Fuel PEI | I8: Dagon | J8: Haifa | L8: months | M8: Year
A9: 1545 | D9: 5259 | J9: 7062 | M9: 2000
A10: 1438 | D10: 5241 | J10: 6658 | M10: 2001
A11: 1413 | D11: 5471 | J11: 6979 | M11: 2002
A12: 1760.467 | D12: 5176.897 | J12: 8029.6062 | M12: 2003
A13: 1784.3859 | D13: 5721.8554 | J13: 8200.1941 | M13: 2004
A14: =SUM(A36:A39) -> 2202.756 | D14: =SUM(D36:D39) -> 5352.966 | J14: =SUM(J36:J39) -> 9079.456 | M14: 2005
A15: 1639.335 | D15: 5516 | J15: 8693 | M15: 2006
A16: =SUM(A46:A49) -> 2309.689 | D16: =SUM(D46:D49) -> 6126.368 | J16: =SUM(J46:J49) -> 9311.392 | M16: 2007
A17: =A54+A58+A62+A66 -> 2356.933 | D17: =D54+D58+D62+D66 -> 5804.292 | E17: 0 | J17: =J54+J58+J62+J66 -> 9970.744 | M17: 2008
A18: =A71+A75+A79+A83 -> 1585.651 | D18: =D71+D75+D79+D83 -> 4918.014 | E18: =E71+E75+E79+E83 -> 19.502 | J18: =J71+J75+J79+J83 -> 8875.588 | M18: 2009
A19: =A88+A92+A96+A100 -> 2254.737 | D19: =D88+D92+D96+D100 -> 7307.861 | E19: =E88+E92+E96+E100 -> 9.237 | J19: =J88+J92+J96+J100 -> 9697.4469 | K19: =J19+E19+D19+A19 -> 19269.282 | M19: 2010
A20: =A105+A109+A113+A117 -> 2119.32 | D20: =D105+D109+D113+D117 -> 7224.6731 | E20: =E105+E109+E113+E117 -> 24.571 | J20: =J105+J109+J113+J117 -> 10221.252 | K20: =J20+E20+D20+A20 -> 19589.816 | M20: 2011
A21: =A122+A126+A130+A134 -> 1456.209 | D21: =D122+D126+D130+D134 -> 7231.6741 | E21: =E122+E126+E130+E134 -> 32.164 | J21: =J122+J126+J130+J134 -> 10709.436 | K21: =J21+E21+D21+A21 -> 19429.483 | M21: 2012
A22: =A139+A143+A147+A151 -> 1921.3107 | D22: =D139+D143+D147+D151 -> 6829.0077 | E22: =E139+E143+E147+E151 -> 11.793 | J22: =J139+J143+J147+J151 -> 11700.985 | K22: =J22+E22+D22+A22 -> 20463.097 | M22: 2013
A23: =A156+A160+A164+A168 -> 2126.0743 | D23: =D156+D160+D164+D168 -> 8264.3546 | E23: =E156+E160+E164+E168 -> 16.855 | J23: =J156+J160+J164+J168 -> 10877.018 | K23: =J23+E23+D23+A23 -> 21284.302 | M23: 2014
A24: =A173+A177+A181+A185 -> 1891.2727 | D24: =D173+D177+D181+D185 -> 7948.6514 | E24: =E173+E177+E181+E185 -> 5.71 | J24: =J173+J177+J181+J185 -> 10327.323 | K24: =J24+E24+D24+A24 -> 20172.957 | M24: 2015
A25: =A190+A194+A198+A202 -> 1891.1233 | D25: =D190+D194+D198+D202 -> 8694.1246 | E25: =E190+E194+E198+E202 -> 2.337 | J25: =J190+J194+J198+J202 -> 10149.986 | K25: =J25+E25+D25+A25 -> 20737.57 | M25: 2016
A26: =A207+A211+A215+A219 -> 2018.11 | D26: =D207+D211+D215+D219 -> 8375.2218 | E26: =E207+E211+E215+E219 -> 0.136 | J26: =J207+J211+J215+J219 -> 10112.283 | K26: =J26+E26+D26+A26 -> 20505.75 | M26: 2017
A27: =A224+A228+A232+A236 -> 2114.266 | D27: =D224+D228+D232+D236 -> 7702.5772 | E27: =E224+E228+E232+E236 -> 2.137 | J27: =J224+J228+J232+J236 -> 10414.278 | K27: =J27+E27+D27+A27 -> 20233.259 | M27: 2018
A28: =A241+A245+A249+A253 -> 1750.9701 | D28: =D241+D245+D249+D253 -> 7751.2784 | E28: =E241+E245+E249+E253 -> 0 | J28: =J241+J245+J249+J253 -> 10107.839 | K28: =J28+E28+D28+A28 -> 19610.087 | M28: 2019
A29: =A258+A262+A266+A270 -> 2075.403 | D29: =D258+D262+D266+D270 -> 7908.6101 | E29: =E258+E262+E266+E270 -> 0 | J29: =J258+J262+J266+J270 -> 9139.3927 | K29: =J29+E29+D29+A29 -> 19123.406 | M29: 2020
A30: =A275+A279+A283+A287 -> 1632.395 | B30: =B275+B279+B283+B287 -> 811.53341 | C30: =C275+C279+C283+C287 -> 48.8156 | D30: =D275+D279+D283+D287 -> 7367.4067 | E30: =E275+E279+E283+E287 -> 0 | F30: =F275+F279+F283+F287 -> 70.735 | G30: =G275+G279+G283+G287 -> 373.654 | H30: =H275+H279+H283+H287 -> 3312.6759 | ... K30: =K275+K279+K283+K287 -> 19140.295 | M30: 2021
A31: =A292+A296+A300+A304 -> 1546.947 | B31: =B292+B296+B300+B304 -> 857.39245 | C31: =C292+C296+C300+C304 -> 267.22116 | D31: =D292+D296+D300+D304 -> 6968.3797 | E31: =E292+E296+E300+E304 -> 0 | F31: =F292+F296+F300+F304 -> 1453.9682 | G31: =G292+G296+G300+G304 -> 443.477 | H31: =H292+H296+H300+H304 -> 3416.4816 | ... K31: =K292+K296+K300+K304 -> 19246.655 | M31: 2022
A32: =A309+A313+A317+A321 -> 1582.62 | B32: =B309+B313+B317+B321 -> 1050.7755 | C32: =C309+C313+C317+C321 -> 928.01199 | D32: =D309+D313+D317+D321 -> 6358.6659 | E32: =E309+E313+E317+E321 -> 0.391 | F32: =F309+F313+F317+F321 -> 3782.2932 | G32: =G309+G313+G317+G321 -> 430.073 | H32: =H309+H313+H317+H321 -> 2774.2081 | ... K32: =K309+K313+K317+K321 -> 19677.846 | M32: 2023
A33: =A326+A330+A334+A338 -> 643.38 | B33: =B326+B330+B334+B338 -> 692.03629 | C33: =C326+C330+C334+C338 -> 1680.5997 | D33: =D326+D330+D334+D338 -> 6957.4306 | E33: =E326+E330+E334+E338 -> 0.432816 | F33: =F326+F330+F334+F338 -> 2131.7059 | G33: =G326+G330+G334+G338 -> 362.805 | H33: =H326+H330+H334+H338 -> 2435.3731 | ... K33: =K326+K330+K334+K338 -> 17380.451 | M33: 2024
A34: =A343+A347+A348+A349 -> 320.219 | B34: =B343+B347+B348+B349 -> 526.4194 | C34: =C343+C347+C348+C349 -> 1216.4557 | D34: =D343+D347+D348+D349 -> 4633.9719 | E34: =E343+E347+E348+E349 -> 0 | F34: =F343+F347+F348+F349 -> 1447.4816 | G34: =G343+G347+G348+G349 -> 204.025 | H34: =H343+H347+H348+H349 -> 940.78286 | ... K34: =K343+K347+K348+K349 -> 11004.966 | L34: 01-08 | M34: 2025
A36: 600.768 | D36: 1459.112 | J36: 2044.352 | L36: 01-03 | M36: 2005
A37: 391.86 | D37: 1587.206 | J37: 2557.609 | L37: 04-06
A38: 651.862 | D38: 1193.714 | J38: 2357.055 | L38: 07-09
A39: 558.266 | D39: 1112.934 | J39: 2120.44 | L39: 10-12
A41: 253.335 | D41: 1170 | J41: 2221 | L41: 01-03 | M41: 2006
A42: 356 | D42: 1294 | J42: 2688 | L42: 04-06
...

Sheet התפלגות תאגידים H1-2025 
